Traceback (most recent call last):
  File "/home/filippo/miniconda3/envs/sta2003/lib/python3.10/site-packages/jupyter_cache/executors/utils.py", line 58, in single_nb_execution
    executenb(
  File "/home/filippo/miniconda3/envs/sta2003/lib/python3.10/site-packages/nbclient/client.py", line 1305, in execute
    return NotebookClient(nb=nb, resources=resources, km=km, **kwargs).execute()
  File "/home/filippo/miniconda3/envs/sta2003/lib/python3.10/site-packages/jupyter_core/utils/__init__.py", line 165, in wrapped
    return loop.run_until_complete(inner)
  File "/home/filippo/miniconda3/envs/sta2003/lib/python3.10/asyncio/base_events.py", line 649, in run_until_complete
    return future.result()
  File "/home/filippo/miniconda3/envs/sta2003/lib/python3.10/site-packages/nbclient/client.py", line 705, in async_execute
    await self.async_execute_cell(
  File "/home/filippo/miniconda3/envs/sta2003/lib/python3.10/site-packages/nbclient/client.py", line 1058, in async_execute_cell
    await self._check_raise_for_error(cell, cell_index, exec_reply)
  File "/home/filippo/miniconda3/envs/sta2003/lib/python3.10/site-packages/nbclient/client.py", line 914, in _check_raise_for_error
    raise CellExecutionError.from_cell_and_msg(cell, exec_reply_content)
nbclient.exceptions.CellExecutionError: An error occurred while executing the following cell:
------------------
plot_uwave()
------------------

----- stdout -----
Failed to download UWAVE dataset.
------------------

[0;31m---------------------------------------------------------------------------[0m
[0;31mTypeError[0m                                 Traceback (most recent call last)
Cell [0;32mIn[25], line 1[0m
[0;32m----> 1[0m [43mplot_uwave[49m[43m([49m[43m)[49m

Cell [0;32mIn[24], line 2[0m, in [0;36mplot_uwave[0;34m()[0m
[1;32m      1[0m [38;5;28;01mdef[39;00m [38;5;21mplot_uwave[39m():
[0;32m----> 2[0m     X, Y, _, _ [38;5;241m=[39m DataLoader()[38;5;241m.[39mget_data([38;5;124m'[39m[38;5;124mUWAVE[39m[38;5;124m'[39m)
[1;32m      3[0m     fig, axes [38;5;241m=[39m plt[38;5;241m.[39msubplots([38;5;241m3[39m, [38;5;241m8[39m, figsize[38;5;241m=[39m([38;5;241m15[39m, [38;5;241m5[39m), subplot_kw[38;5;241m=[39m{[38;5;124m'[39m[38;5;124mprojection[39m[38;5;124m'[39m: [38;5;124m'[39m[38;5;124m3d[39m[38;5;124m'[39m})
[1;32m      4[0m     [38;5;28;01mfor[39;00m i [38;5;129;01min[39;00m [38;5;28mrange[39m([38;5;28mlen[39m(np[38;5;241m.[39munique(Y))):

[0;31mTypeError[0m: cannot unpack non-iterable NoneType object

